Workbook

Sheet Raw_Data_Original
A1: title | B1: magnitude | C1: date_time | D1: cdi | E1: mmi | F1: alert | G1: tsunami | H1: sig | I1: net | J1: nst | K1: dmin | L1: gap | M1: magType | N1: depth | O1: latitude | P1: longitude | Q1: location | R1: continent | S1: country
A2: M 6.5 - 42 km W of Sola, Vanuatu | B2: 6.5 | C2: 16/08/2023 12:47 | D2: 7 | E2: 4 | F2: green | G2: 0 | H2: 657 | I2: us | J2: 114 | K2: 7.177 | L2: 25 | M2: mww | N2: 192.955 | O2: -13.8814 | P2: 167.158 | Q2: Sola, Vanuatu | S2: Vanuatu
A3: M 6.5 - 43 km S of Intipucá, El Salvador | B3: 6.5 | C3: 19/07/2023 00:22 | D3: 8 | E3: 6 | F3: yellow | G3: 0 | H3: 775 | I3: us | J3: 92 | K3: 0.679 | L3: 40 | M3: mww | N3: 69.727 | O3: 12.814 | P3: -88.1265 | Q3: Intipucá, El Salvador
A4: M 6.6 - 25 km ESE of Loncopué, Argentina | B4: 6.6 | C4: 17/07/2023 03:05 | D4: 7 | E4: 5 | F4: green | G4: 0 | H4: 899 | I4: us | J4: 70 | K4: 1.634 | L4: 28 | M4: mww | N4: 171.371 | O4: -38.1911 | P4: -70.3731 | Q4: Loncopué, Argentina | R4: South America | S4: Argentina
A5: M 7.2 - 98 km S of Sand Point, Alaska | B5: 7.2 | C5: 16/07/2023 06:48 | D5: 6 | E5: 6 | F5: green | G5: 1 | H5: 860 | I5: us | J5: 173 | K5: 0.907 | L5: 36 | M5: mww | N5: 32.571 | O5: 54.3844 | P5: -160.699 | Q5: Sand Point, Alaska
A6: M 7.3 - Alaska Peninsula | B6: 7.3 | C6: 16/07/2023 06:48 | D6: 0 | E6: 5 | G6: 1 | H6: 820 | I6: at | J6: 79 | K6: 0.879451 | L6: 172.8 | M6: Mi | N6: 21 | O6: 54.49 | P6: -160.796 | Q6: Alaska Peninsula
A7: M 6.6 - 277 km NNE of Codrington, Antigua and Barbuda | B7: 6.6 | C7: 10/07/2023 20:28 | D7: 5 | E7: 4 | F7: green | G7: 1 | H7: 802 | I7: us | J7: 95 | K7: 2.454 | L7: 37 | M7: mww | N7: 10 | O7: 20.0196 | P7: -61.0955 | Q7: Codrington, Antigua and Barbuda
A8: M 6.9 - Tonga | B8: 6.9 | C8: 02/07/2023 10:27 | D8: 4 | E8: 4 | F8: green | G8: 1 | H8: 741 | I8: us | J8: 136 | K8: 1.179 | L8: 23 | M8: mww | N8: 229 | O8: -17.853 | P8: -174.937 | Q8: Tonga
A9: M 7.2 - south of the Fiji Islands | B9: 7.2 | C9: 15/06/2023 18:06 | D9: 8 | E9: 6 | F9: green | G9: 1 | H9: 804 | I9: us | J9: 85 | K9: 2.59 | L9: 24 | M9: mww | N9: 167.404 | O9: -22.9824 | P9: -177.208 | Q9: the Fiji Islands
A10: M 6.6 - Panama-Colombia border region | B10: 6.6 | C10: 25/05/2023 03:05 | D10: 6 | E10: 6 | F10: green | G10: 1 | H10: 733 | I10: us | J10: 50 | K10: 2.163 | L10: 129 | M10: mww | N10: 10 | O10: 8.8894 | P10: -77.1231 | Q10: Panama-Colombia border region | S10: Colombia
A11: M 7.1 - southeast of the Loyalty Islands | B11: 7.1 | C11: 20/05/2023 01:51 | D11: 3 | E11: 4 | F11: green | G11: 1 | H11: 777 | I11: us | J11: 98 | K11: 2.812 | L11: 56 | M11: mww | N11: 35.981 | O11: -23.0622 | P11: 170.456 | Q11: the Loyalty Islands
A12: M 7.7 - southeast of the Loyalty Islands | B12: 7.7 | C12: 19/05/2023 02:57 | D12: 5 | E12: 4 | F12: green | G12: 1 | H12: 927 | I12: us | J12: 277 | K12: 3.111 | L12: 15 | M12: mww | N12: 18.027 | O12: -23.2286 | P12: 170.694 | Q12: the Loyalty Islands
A13: M 7.6 - 95 km WNW of Hihifo, Tonga | B13: 7.6 | C13: 10/05/2023 16:02 | D13: 8 | E13: 6 | F13: green | G13: 1 | H13: 907 | I13: us | J13: 111 | K13: 3.631 | L13: 17 | M13: mww | N13: 210.097 | O13: -15.6002 | P13: -174.608 | Q13: Hihifo, Tonga
A14: M 6.6 - south of the Fiji Islands | B14: 6.6 | C14: 28/04/2023 03:13 | D14: 0 | E14: 2 | F14: green | G14: 0 | H14: 670 | I14: us | J14: 52 | K14: 5.123 | L14: 50 | M14: mww | N14: 598.467 | O14: -25.2657 | P14: 178.424 | Q14: the Fiji Islands
A15: M 7.1 - 170 km SSE of Teluk Dalam, Indonesia | B15: 7.1 | C15: 24/04/2023 20:00 | D15: 9 | E15: 7 | F15: green | G15: 0 | H15: 838 | I15: us | J15: 70 | K15: 2.282 | L15: 58 | M15: mww | N15: 15.462 | O15: -0.781 | P15: 98.5339 | Q15: Teluk Dalam, Indonesia | S15: Indonesia
A16: M 7.1 - Kermadec Islands, New Zealand | B16: 7.1 | C16: 24/04/2023 00:41 | D16: 8 | E16: 7 | F16: green | G16: 1 | H16: 777 | I16: us | J16: 126 | K16: 0.708 | L16: 23 | M16: mww | N16: 43.063 | O16: -30.0249 | P16: -177.897 | Q16: Kermadec Islands, New Zealand
A17: M 6.7 - south of the Fiji Islands | B17: 6.7 | C17: 18/04/2023 04:31 | D17: 0 | E17: 3 | F17: green | G17: 1 | H17: 691 | I17: us | J17: 166 | K17: 4.719 | L17: 10 | M17: mww | N17: 595.854 | O17: -22.2844 | P17: 179.391 | Q17: the Fiji Islands
A18: M 7.0 - 96 km N of Tuban, Indonesia | B18: 7 | C18: 14/04/2023 09:55 | D18: 5 | E18: 3 | F18: green | G18: 0 | H18: 818 | I18: us | J18: 131 | K18: 1.881 | L18: 31 | M18: mww | N18: 594.028 | O18: -6.0255 | P18: 112.033 | Q18: Tuban, Indonesia | S18: Indonesia
A19: M 6.5 - near the east coast of the Kamchatka Peninsula, Russia | B19: 6.5 | C19: 03/04/2023 03:06 | D19: 7 | E19: 6 | F19: yellow | G19: 1 | H19: 655 | I19: us | J19: 104 | K19: 0.266 | L19: 30 | M19: mww | N19: 105.631 | O19: 52.7772 | P19: 158.484 | Q19: the Kamchatka Peninsula, Russia | R19: Asia | S19: Russian Federation (the)
A20: M 7.0 - New Guinea, Papua New Guinea | B20: 7 | C20: 02/04/2023 18:04 | D20: 7 | E20: 7 | F20: green | G20: 1 | H20: 781 | I20: us | J20: 105 | K20: 6.45 | L20: 31 | M20: mww | N20: 62.603 | O20: -4.2924 | P20: 143.155 | Q20: New Guinea, Papua New Guinea | R20: Asia | S20: Papua New Guinea
A21: M 6.5 - 84 km NNW of San Antonio de los Cobres, Argentina | B21: 6.5 | C21: 22/03/2023 16:00 | D21: 4 | E21: 4 | F21: green | G21: 0 | H21: 656 | I21: us | J21: 97 | K21: 1.622 | L21: 33 | M21: mww | N21: 209.976 | O21: -23.4797 | P21: -66.5108 | Q21: San Antonio de los Cobres, Argentina | R21: South America | S21: Argentina
A22: M 6.5 - 40 km SSE of Jurm, Afghanistan | B22: 6.5 | C22: 21/03/2023 16:47 | D22: 7 | E22: 5 | F22: green | G22: 0 | H22: 1350 | I22: us | J22: 134 | K22: 2.53 | L22: 13 | M22: mww | N22: 187.589 | O22: 36.5227 | P22: 70.9787 | Q22: Jurm, Afghanistan | R22: Asia | S22: Afghanistan
A23: M 6.8 - near the coast of Ecuador | B23: 6.8 | C23: 18/03/2023 17:12 | D23: 9 | E23: 7 | F23: orange | G23: 1 | H23: 1159 | I23: us | J23: 152 | K23: 0.709 | L23: 28 | M23: mww | N23: 65.842 | O23: -2.851 | P23: -79.8001 | Q23: Ecuador | R23: South America | S23: Ecuador
A24: M 7.0 - Kermadec Islands region | B24: 7 | C24: 16/03/2023 00:56 | D24: 8 | E24: 5 | F24: green | G24: 1 | H24: 756 | I24: us | J24: 116 | K24: 1.789 | L24: 22 | M24: mww | N24: 22.065 | O24: -30.1147 | P24: -176.112 | Q24: Kermadec Islands region
A25: M 6.9 - Kermadec Islands, New Zealand | B25: 6.9 | C25: 04/03/2023 06:41 | D25: 5 | E25: 5 | F25: green | G25: 1 | H25: 735 | I25: us | J25: 108 | K25: 0.784 | L25: 18 | M25: mww | N25: 205.681 | O25: -29.4748 | P25: -178.787 | Q25: Kermadec Islands, New Zealand
A26: M 6.5 - 86 km WSW of Port-Olry, Vanuatu | B26: 6.5 | C26: 02/03/2023 18:04 | D26: 7 | E26: 6 | F26: green | G26: 1 | H26: 653 | I26: us | J26: 66 | K26: 5.483 | L26: 45 | M26: mww | N26: 10 | O26: -15.3597 | P26: 166.385 | Q26: Port-Olry, Vanuatu
A27: M 6.5 - 108 km NW of Kimbe, Papua New Guinea | B27: 6.5 | C27: 01/03/2023 05:36 | D27: 4 | E27: 2 | F27: green | G27: 1 | H27: 652 | I27: us | J27: 115 | K27: 2.739 | L27: 20 | M27: mww | N27: 598.925 | O27: -4.8138 | P27: 149.487 | Q27: Kimbe, Papua New Guinea | S27: Papua New Guinea
A28: M 6.8 - 67 km W of Murghob, Tajikistan | B28: 6.8 | C28: 23/02/2023 00:37 | D28: 9 | E28: 7 | F28: green | G28: 0 | H28: 737 | I28: us | J28: 128 | K28: 1.783 | L28: 20 | M28: mww | N28: 20.522 | O28: 38.0726 | P28: 73.2077 | Q28: Murghob, Tajikistan | R28: Asia | S28: Tajikistan
A29: M 7.5 - 4 km SSE of Ekinözü, Turkey | B29: 7.5 | C29: 06/02/2023 10:24 | D29: 9 | E29: 9 | F29: orange | G29: 0 | H29: 1411 | I29: us | J29: 135 | K29: 0.85 | L29: 17 | M29: mww | N29: 10 | O29: 38.0235 | P29: 37.203 | Q29: Ekinözü, Turkey | R29: Asia | S29: Turkiye
A30: M 6.7 - 18 km ESE of Nurdağı, Turkey | B30: 6.7 | C30: 06/02/2023 01:28 | D30: 9 | E30: 8 | F30: yellow | G30: 0 | H30: 800 | I30: us | J30: 108 | K30: 0.218 | L30: 44 | M30: mww | N30: 14.497 | O30: 37.4135 | P30: 36.8306 | Q30: Nurdağı, Turkey | R30: Asia | S30: Turkiye
A31: M 7.8 - Central Turkey | B31: 7.8 | C31: 06/02/2023 01:17 | D31: 9 | E31: 9 | F31: red | G31: 0 | H31: 2910 | I31: us | J31: 118 | K31: 1.919 | L31: 32 | M31: mww | N31: 17.925 | O31: 37.2012 | P31: 36.9997 | Q31: Central Turkey | R31: Asia | S31: Turkiye
A32: M 6.8 - | B32: 6.8 | C32: 20/01/2023 22:09 | D32: 4 | E32: 3 | F32: green | G32: 0 | H32: 718 | I32: us | J32: 60 | K32: 5.129 | L32: 61 | M32: mww | N32: 610.671 | O32: -26.7209 | P32: -63.0394 | R32: South America | S32: Argentina
A33: M 7.0 - 153 km NW of Tobelo, Indonesia | B33: 7 | C33: 18/01/2023 06:06 | D33: 3 | E33: 5 | F33: green | G33: 1 | H33: 756 | I33: us | J33: 130 | K33: 1.974 | L33: 17 | M33: mwc | N33: 28.566 | O33: 2.7401 | P33: 127.051 | Q33: Tobelo, Indonesia | S33: Indonesia
A34: M 7.6 - Pulau Pulau Tanimbar, Indonesia | B34: 7.6 | C34: 09/01/2023 17:47 | D34: 5 | E34: 7 | F34: green | G34: 0 | H34: 957 | I34: us | J34: 114 | K34: 1.575 | L34: 21 | M34: mww | N34: 105.249 | O34: -7.0852 | P34: 130.039 | Q34: Pulau Pulau Tanimbar, Indonesia | S34: Indonesia
A35: M 7.0 - Vanuatu | B35: 7 | C35: 08/01/2023 12:32 | D35: 8 | E35: 7 | F35: green | G35: 1 | H35: 768 | I35: us | J35: 116 | K35: 6.096 | L35: 36 | M35: mww | N35: 29 | O35: -14.9383 | P35: 166.878 | Q35: Vanuatu | S35: Vanuatu
A36: M 6.8 - 109 km NE of Hihifo, Tonga | B36: 6.8 | C36: 04/12/2022 19:24 | D36: 5 | E36: 5 | F36: green | G36: 1 | H36: 720 | I36: us | J36: 152 | K36: 2.587 | L36: 26 | M36: mww | N36: 38 | O36: -15.3983 | P36: -172.968 | Q36: Hihifo, Tonga
A37: M 7.0 - 18 km SW of Malango, Solomon Islands | B37: 7 | C37: 22/11/2022 02:03 | D37: 8 | E37: 7 | F37: green | G37: 1 | H37: 768 | I37: us | J37: 117 | K37: 0.509 | L37: 17 | M37: mww | N37: 14 | O37: -9.7963 | P37: 159.596 | Q37: Malango, Solomon Islands | R37: Oceania | S37: Solomon Islands
A38: M 6.9 - 204 km SW of Bengkulu, Indonesia | B38: 6.9 | C38: 18/11/2022 13:37 | D38: 4 | E38: 4 | F38: green | G38: 0 | H38: 735 | I38: us | J38: 99 | K38: 2.229 | L38: 34 | M38: mww | N38: 25 | O38: -4.9559 | P38: 100.738 | Q38: Bengkulu, Indonesia
A39: M 7.0 - | B39: 7 | C39: 12/11/2022 07:09 | D39: 3 | E39: 3 | F39: green | G39: 1 | H39: 755 | I39: us | J39: 147 | K39: 3.125 | L39: 18 | M39: mww | N39: 579 | O39: -20.0508 | P39: -178.346 | R39: Oceania | S39: Fiji
A40: M 7.3 - 205 km ESE of Neiafu, Tonga | B40: 7.3 | C40: 11/11/2022 10:48 | D40: 5 | E40: 5 | F40: green | G40: 1 | H40: 833 | I40: us | J40: 149 | K40: 1.865 | L40: 21 | M40: mww | N40: 37 | O40: -19.2918 | P40: -172.129 | Q40: Neiafu, Tonga
...

Sheet Working_Data
A1: title | B1: magnitude | C1: date_time | D1: cdi | E1: mmi | F1: alert | G1: tsunami | H1: sig | I1: net | J1: nst | K1: dmin | L1: gap | M1: magType | N1: depth | O1: latitude | P1: longitude | Q1: location | R1: continent | S1: country | T1: Converted_DateTime | U1: Title_Pattern | V1: magType_Normalized | W1: Duplicate_Count | X1: Duplicate_Flag | Y1: Magnitude_Band | Z1: Year
A2: M 6.5 - 42 km W of Sola, Vanuatu | B2: 6.5 | C2: 16/08/2023 12:47 | D2: 7 | E2: 4 | F2: green | G2: 0 | H2: 657 | I2: us | J2: 114 | K2: 7.177 | L2: 25 | M2: mww | N2: 192.955 | O2: -13.8814 | P2: 167.158 | Q2: Sola, Vanuatu | S2: Vanuatu | T2: =IF(C2="","",DATE(VALUE(MID(C2,7,4)),VALUE(MID(C2,4,2)),VALUE(MID(C2,1,2)))+TIME(VALUE(MID(C2,12,2)),VALUE(MID(C2,15,2)),0)) -> 45154.533 | U2: =IFERROR(IF(ISNUMBER(VALUE(TRIM(MID(A2,FIND("-",A2)+1,FIND("km",A2)-FIND("-",A2)-1)))),"Distance + direction + city","Named-region"),"Named-region") -> Distance + direction + city | V2: =LOWER(M2) -> mww | W2: =COUNTIFS($A$2:$A$1001,A2,$C$2:$C$1001,C2) -> 1 | X2: =IF(W2>1,"Duplicate","Unique") -> Unique | Y2: =IF(B2<6.5,"<6.5",IF(B2<7,"6.5–6.9",IF(B2<7.5,"7.0–7.4",IF(B2<8,"7.5–7.9","8.0+")))) -> 6.5–6.9 | Z2: =IF(T2="","",YEAR(T2)) -> 2023
A3: M 6.5 - 43 km S of Intipucá, El Salvador | B3: 6.5 | C3: 19/07/2023 00:22 | D3: 8 | E3: 6 | F3: yellow | G3: 0 | H3: 775 | I3: us | J3: 92 | K3: 0.679 | L3: 40 | M3: mww | N3: 69.727 | O3: 12.814 | P3: -88.1265 | Q3: Intipucá, El Salvador | T3: =IF(C3="","",DATE(VALUE(MID(C3,7,4)),VALUE(MID(C3,4,2)),VALUE(MID(C3,1,2)))+TIME(VALUE(MID(C3,12,2)),VALUE(MID(C3,15,2)),0)) -> 45126.015 | U3: =IFERROR(IF(ISNUMBER(VALUE(TRIM(MID(A3,FIND("-",A3)+1,FIND("km",A3)-FIND("-",A3)-1)))),"Distance + direction + city","Named-region"),"Named-region") -> Distance + direction + city | V3: =LOWER(M3) -> mww | W3: =COUNTIFS($A$2:$A$1001,A3,$C$2:$C$1001,C3) -> 1 | X3: =IF(W3>1,"Duplicate","Unique") -> Unique | Y3: =IF(B3<6.5,"<6.5",IF(B3<7,"6.5–6.9",IF(B3<7.5,"7.0–7.4",IF(B3<8,"7.5–7.9","8.0+")))) -> 6.5–6.9 | Z3: =IF(T3="","",YEAR(T3)) -> 2023
A4: M 6.6 - 25 km ESE of Loncopué, Argentina | B4: 6.6 | C4: 17/07/2023 03:05 | D4: 7 | E4: 5 | F4: green | G4: 0 | H4: 899 | I4: us | J4: 70 | K4: 1.634 | L4: 28 | M4: mww | N4: 171.371 | O4: -38.1911 | P4: -70.3731 | Q4: Loncopué, Argentina | R4: South America | S4: Argentina | T4: =IF(C4="","",DATE(VALUE(MID(C4,7,4)),VALUE(MID(C4,4,2)),VALUE(MID(C4,1,2)))+TIME(VALUE(MID(C4,12,2)),VALUE(MID(C4,15,2)),0)) -> 45124.128 | U4: =IFERROR(IF(ISNUMBER(VALUE(TRIM(MID(A4,FIND("-",A4)+1,FIND("km",A4)-FIND("-",A4)-1)))),"Distance + direction + city","Named-region"),"Named-region") -> Distance + direction + city | V4: =LOWER(M4) -> mww | W4: =COUNTIFS($A$2:$A$1001,A4,$C$2:$C$1001,C4) -> 1 | X4: =IF(W4>1,"Duplicate","Unique") -> Unique | Y4: =IF(B4<6.5,"<6.5",IF(B4<7,"6.5–6.9",IF(B4<7.5,"7.0–7.4",IF(B4<8,"7.5–7.9","8.0+")))) -> 6.5–6.9 | Z4: =IF(T4="","",YEAR(T4)) -> 2023
A5: M 7.2 - 98 km S of Sand Point, Alaska | B5: 7.2 | C5: 16/07/2023 06:48 | D5: 6 | E5: 6 | F5: green | G5: 1 | H5: 860 | I5: us | J5: 173 | K5: 0.907 | L5: 36 | M5: mww | N5: 32.571 | O5: 54.3844 | P5: -160.699 | Q5: Sand Point, Alaska | T5: =IF(C5="","",DATE(VALUE(MID(C5,7,4)),VALUE(MID(C5,4,2)),VALUE(MID(C5,1,2)))+TIME(VALUE(MID(C5,12,2)),VALUE(MID(C5,15,2)),0)) -> 45123.283 | U5: =IFERROR(IF(ISNUMBER(VALUE(TRIM(MID(A5,FIND("-",A5)+1,FIND("km",A5)-FIND("-",A5)-1)))),"Distance + direction + city","Named-region"),"Named-region") -> Distance + direction + city | V5: =LOWER(M5) -> mww | W5: =COUNTIFS($A$2:$A$1001,A5,$C$2:$C$1001,C5) -> 1 | X5: =IF(W5>1,"Duplicate","Unique") -> Unique | Y5: =IF(B5<6.5,"<6.5",IF(B5<7,"6.5–6.9",IF(B5<7.5,"7.0–7.4",IF(B5<8,"7.5–7.9","8.0+")))) -> 7.0–7.4 | Z5: =IF(T5="","",YEAR(T5)) -> 2023
A6: M 7.3 - Alaska Peninsula | B6: 7.3 | C6: 16/07/2023 06:48 | D6: 0 | E6: 5 | G6: 1 | H6: 820 | I6: at | J6: 79 | K6: 0.879451 | L6: 172.8 | M6: Mi | N6: 21 | O6: 54.49 | P6: -160.796 | Q6: Alaska Peninsula | T6: =IF(C6="","",DATE(VALUE(MID(C6,7,4)),VALUE(MID(C6,4,2)),VALUE(MID(C6,1,2)))+TIME(VALUE(MID(C6,12,2)),VALUE(MID(C6,15,2)),0)) -> 45123.283 | U6: =IFERROR(IF(ISNUMBER(VALUE(TRIM(MID(A6,FIND("-",A6)+1,FIND("km",A6)-FIND("-",A6)-1)))),"Distance + direction + city","Named-region"),"Named-region") -> Named-region | V6: =LOWER(M6) -> mi | W6: =COUNTIFS($A$2:$A$1001,A6,$C$2:$C$1001,C6) -> 1 | X6: =IF(W6>1,"Duplicate","Unique") -> Unique | Y6: =IF(B6<6.5,"<6.5",IF(B6<7,"6.5–6.9",IF(B6<7.5,"7.0–7.4",IF(B6<8,"7.5–7.9","8.0+")))) -> 7.0–7.4 | Z6: =IF(T6="","",YEAR(T6)) -> 2023
A7: M 6.6 - 277 km NNE of Codrington, Antigua and Barbuda | B7: 6.6 | C7: 10/07/2023 20:28 | D7: 5 | E7: 4 | F7: green | G7: 1 | H7: 802 | I7: us | J7: 95 | K7: 2.454 | L7: 37 | M7: mww | N7: 10 | O7: 20.0196 | P7: -61.0955 | Q7: Codrington, Antigua and Barbuda | T7: =IF(C7="","",DATE(VALUE(MID(C7,7,4)),VALUE(MID(C7,4,2)),VALUE(MID(C7,1,2)))+TIME(VALUE(MID(C7,12,2)),VALUE(MID(C7,15,2)),0)) -> 45117.853 | U7: =IFERROR(IF(ISNUMBER(VALUE(TRIM(MID(A7,FIND("-",A7)+1,FIND("km",A7)-FIND("-",A7)-1)))),"Distance + direction + city","Named-region"),"Named-region") -> Distance + direction + city | V7: =LOWER(M7) -> mww | W7: =COUNTIFS($A$2:$A$1001,A7,$C$2:$C$1001,C7) -> 1 | X7: =IF(W7>1,"Duplicate","Unique") -> Unique | Y7: =IF(B7<6.5,"<6.5",IF(B7<7,"6.5–6.9",IF(B7<7.5,"7.0–7.4",IF(B7<8,"7.5–7.9","8.0+")))) -> 6.5–6.9 | Z7: =IF(T7="","",YEAR(T7)) -> 2023
A8: M 6.9 - Tonga | B8: 6.9 | C8: 02/07/2023 10:27 | D8: 4 | E8: 4 | F8: green | G8: 1 | H8: 741 | I8: us | J8: 136 | K8: 1.179 | L8: 23 | M8: mww | N8: 229 | O8: -17.853 | P8: -174.937 | Q8: Tonga | T8: =IF(C8="","",DATE(VALUE(MID(C8,7,4)),VALUE(MID(C8,4,2)),VALUE(MID(C8,1,2)))+TIME(VALUE(MID(C8,12,2)),VALUE(MID(C8,15,2)),0)) -> 45109.435 | U8: =IFERROR(IF(ISNUMBER(VALUE(TRIM(MID(A8,FIND("-",A8)+1,FIND("km",A8)-FIND("-",A8)-1)))),"Distance + direction + city","Named-region"),"Named-region") -> Named-region | V8: =LOWER(M8) -> mww | W8: =COUNTIFS($A$2:$A$1001,A8,$C$2:$C$1001,C8) -> 1 | X8: =IF(W8>1,"Duplicate","Unique") -> Unique | Y8: =IF(B8<6.5,"<6.5",IF(B8<7,"6.5–6.9",IF(B8<7.5,"7.0–7.4",IF(B8<8,"7.5–7.9","8.0+")))) -> 6.5–6.9 | Z8: =IF(T8="","",YEAR(T8)) -> 2023
A9: M 7.2 - south of the Fiji Islands | B9: 7.2 | C9: 15/06/2023 18:06 | D9: 8 | E9: 6 | F9: green | G9: 1 | H9: 804 | I9: us | J9: 85 | K9: 2.59 | L9: 24 | M9: mww | N9: 167.404 | O9: -22.9824 | P9: -177.208 | Q9: the Fiji Islands | T9: =IF(C9="","",DATE(VALUE(MID(C9,7,4)),VALUE(MID(C9,4,2)),VALUE(MID(C9,1,2)))+TIME(VALUE(MID(C9,12,2)),VALUE(MID(C9,15,2)),0)) -> 45092.754 | U9: =IFERROR(IF(ISNUMBER(VALUE(TRIM(MID(A9,FIND("-",A9)+1,FIND("km",A9)-FIND("-",A9)-1)))),"Distance + direction + city","Named-region"),"Named-region") -> Named-region | V9: =LOWER(M9) -> mww | W9: =COUNTIFS($A$2:$A$1001,A9,$C$2:$C$1001,C9) -> 1 | X9: =IF(W9>1,"Duplicate","Unique") -> Unique | Y9: =IF(B9<6.5,"<6.5",IF(B9<7,"6.5–6.9",IF(B9<7.5,"7.0–7.4",IF(B9<8,"7.5–7.9","8.0+")))) -> 7.0–7.4 | Z9: =IF(T9="","",YEAR(T9)) -> 2023
A10: M 6.6 - Panama-Colombia border region | B10: 6.6 | C10: 25/05/2023 03:05 | D10: 6 | E10: 6 | F10: green | G10: 1 | H10: 733 | I10: us | J10: 50 | K10: 2.163 | L10: 129 | M10: mww | N10: 10 | O10: 8.8894 | P10: -77.1231 | Q10: Panama-Colombia border region | S10: Colombia | T10: =IF(C10="","",DATE(VALUE(MID(C10,7,4)),VALUE(MID(C10,4,2)),VALUE(MID(C10,1,2)))+TIME(VALUE(MID(C10,12,2)),VALUE(MID(C10,15,2)),0)) -> 45071.128 | U10: =IFERROR(IF(ISNUMBER(VALUE(TRIM(MID(A10,FIND("-",A10)+1,FIND("km",A10)-FIND("-",A10)-1)))),"Distance + direction + city","Named-region"),"Named-region") -> Named-region | V10: =LOWER(M10) -> mww | W10: =COUNTIFS($A$2:$A$1001,A10,$C$2:$C$1001,C10) -> 1 | X10: =IF(W10>1,"Duplicate","Unique") -> Unique | Y10: =IF(B10<6.5,"<6.5",IF(B10<7,"6.5–6.9",IF(B10<7.5,"7.0–7.4",IF(B10<8,"7.5–7.9","8.0+")))) -> 6.5–6.9 | Z10: =IF(T10="","",YEAR(T10)) -> 2023
A11: M 7.1 - southeast of the Loyalty Islands | B11: 7.1 | C11: 20/05/2023 01:51 | D11: 3 | E11: 4 | F11: green | G11: 1 | H11: 777 | I11: us | J11: 98 | K11: 2.812 | L11: 56 | M11: mww | N11: 35.981 | O11: -23.0622 | P11: 170.456 | Q11: the Loyalty Islands | T11: =IF(C11="","",DATE(VALUE(MID(C11,7,4)),VALUE(MID(C11,4,2)),VALUE(MID(C11,1,2)))+TIME(VALUE(MID(C11,12,2)),VALUE(MID(C11,15,2)),0)) -> 45066.077 | U11: =IFERROR(IF(ISNUMBER(VALUE(TRIM(MID(A11,FIND("-",A11)+1,FIND("km",A11)-FIND("-",A11)-1)))),"Distance + direction + city","Named-region"),"Named-region") -> Named-region | V11: =LOWER(M11) -> mww | W11: =COUNTIFS($A$2:$A$1001,A11,$C$2:$C$1001,C11) -> 1 | X11: =IF(W11>1,"Duplicate","Unique") -> Unique | Y11: =IF(B11<6.5,"<6.5",IF(B11<7,"6.5–6.9",IF(B11<7.5,"7.0–7.4",IF(B11<8,"7.5–7.9","8.0+")))) -> 7.0–7.4 | Z11: =IF(T11="","",YEAR(T11)) -> 2023
A12: M 7.7 - southeast of the Loyalty Islands | B12: 7.7 | C12: 19/05/2023 02:57 | D12: 5 | E12: 4 | F12: green | G12: 1 | H12: 927 | I12: us | J12: 277 | K12: 3.111 | L12: 15 | M12: mww | N12: 18.027 | O12: -23.2286 | P12: 170.694 | Q12: the Loyalty Islands | T12: =IF(C12="","",DATE(VALUE(MID(C12,7,4)),VALUE(MID(C12,4,2)),VALUE(MID(C12,1,2)))+TIME(VALUE(MID(C12,12,2)),VALUE(MID(C12,15,2)),0)) -> 45065.123 | U12: =IFERROR(IF(ISNUMBER(VALUE(TRIM(MID(A12,FIND("-",A12)+1,FIND("km",A12)-FIND("-",A12)-1)))),"Distance + direction + city","Named-region"),"Named-region") -> Named-region | V12: =LOWER(M12) -> mww | W12: =COUNTIFS($A$2:$A$1001,A12,$C$2:$C$1001,C12) -> 1 | X12: =IF(W12>1,"Duplicate","Unique") -> Unique | Y12: =IF(B12<6.5,"<6.5",IF(B12<7,"6.5–6.9",IF(B12<7.5,"7.0–7.4",IF(B12<8,"7.5–7.9","8.0+")))) -> 7.5–7.9 | Z12: =IF(T12="","",YEAR(T12)) -> 2023
A13: M 7.6 - 95 km WNW of Hihifo, Tonga | B13: 7.6 | C13: 10/05/2023 16:02 | D13: 8 | E13: 6 | F13: green | G13: 1 | H13: 907 | I13: us | J13: 111 | K13: 3.631 | L13: 17 | M13: mww | N13: 210.097 | O13: -15.6002 | P13: -174.608 | Q13: Hihifo, Tonga | T13: =IF(C13="","",DATE(VALUE(MID(C13,7,4)),VALUE(MID(C13,4,2)),VALUE(MID(C13,1,2)))+TIME(VALUE(MID(C13,12,2)),VALUE(MID(C13,15,2)),0)) -> 45056.668 | U13: =IFERROR(IF(ISNUMBER(VALUE(TRIM(MID(A13,FIND("-",A13)+1,FIND("km",A13)-FIND("-",A13)-1)))),"Distance + direction + city","Named-region"),"Named-region") -> Distance + direction + city | V13: =LOWER(M13) -> mww | W13: =COUNTIFS($A$2:$A$1001,A13,$C$2:$C$1001,C13) -> 1 | X13: =IF(W13>1,"Duplicate","Unique") -> Unique | Y13: =IF(B13<6.5,"<6.5",IF(B13<7,"6.5–6.9",IF(B13<7.5,"7.0–7.4",IF(B13<8,"7.5–7.9","8.0+")))) -> 7.5–7.9 | Z13: =IF(T13="","",YEAR(T13)) -> 2023
A14: M 6.6 - south of the Fiji Islands | B14: 6.6 | C14: 28/04/2023 03:13 | D14: 0 | E14: 2 | F14: green | G14: 0 | H14: 670 | I14: us | J14: 52 | K14: 5.123 | L14: 50 | M14: mww | N14: 598.467 | O14: -25.2657 | P14: 178.424 | Q14: the Fiji Islands | T14: =IF(C14="","",DATE(VALUE(MID(C14,7,4)),VALUE(MID(C14,4,2)),VALUE(MID(C14,1,2)))+TIME(VALUE(MID(C14,12,2)),VALUE(MID(C14,15,2)),0)) -> 45044.134 | U14: =IFERROR(IF(ISNUMBER(VALUE(TRIM(MID(A14,FIND("-",A14)+1,FIND("km",A14)-FIND("-",A14)-1)))),"Distance + direction + city","Named-region"),"Named-region") -> Named-region | V14: =LOWER(M14) -> mww | W14: =COUNTIFS($A$2:$A$1001,A14,$C$2:$C$1001,C14) -> 1 | X14: =IF(W14>1,"Duplicate","Unique") -> Unique | Y14: =IF(B14<6.5,"<6.5",IF(B14<7,"6.5–6.9",IF(B14<7.5,"7.0–7.4",IF(B14<8,"7.5–7.9","8.0+")))) -> 6.5–6.9 | Z14: =IF(T14="","",YEAR(T14)) -> 2023
A15: M 7.1 - 170 km SSE of Teluk Dalam, Indonesia | B15: 7.1 | C15: 24/04/2023 20:00 | D15: 9 | E15: 7 | F15: green | G15: 0 | H15: 838 | I15: us | J15: 70 | K15: 2.282 | L15: 58 | M15: mww | N15: 15.462 | O15: -0.781 | P15: 98.5339 | Q15: Teluk Dalam, Indonesia | S15: Indonesia | T15: =IF(C15="","",DATE(VALUE(MID(C15,7,4)),VALUE(MID(C15,4,2)),VALUE(MID(C15,1,2)))+TIME(VALUE(MID(C15,12,2)),VALUE(MID(C15,15,2)),0)) -> 45040.833 | U15: =IFERROR(IF(ISNUMBER(VALUE(TRIM(MID(A15,FIND("-",A15)+1,FIND("km",A15)-FIND("-",A15)-1)))),"Distance + direction + city","Named-region"),"Named-region") -> Distance + direction + city | V15: =LOWER(M15) -> mww | W15: =COUNTIFS($A$2:$A$1001,A15,$C$2:$C$1001,C15) -> 1 | X15: =IF(W15>1,"Duplicate","Unique") -> Unique | Y15: =IF(B15<6.5,"<6.5",IF(B15<7,"6.5–6.9",IF(B15<7.5,"7.0–7.4",IF(B15<8,"7.5–7.9","8.0+")))) -> 7.0–7.4 | Z15: =IF(T15="","",YEAR(T15)) -> 2023
A16: M 7.1 - Kermadec Islands, New Zealand | B16: 7.1 | C16: 24/04/2023 00:41 | D16: 8 | E16: 7 | F16: green | G16: 1 | H16: 777 | I16: us | J16: 126 | K16: 0.708 | L16: 23 | M16: mww | N16: 43.063 | O16: -30.0249 | P16: -177.897 | Q16: Kermadec Islands, New Zealand | T16: =IF(C16="","",DATE(VALUE(MID(C16,7,4)),VALUE(MID(C16,4,2)),VALUE(MID(C16,1,2)))+TIME(VALUE(MID(C16,12,2)),VALUE(MID(C16,15,2)),0)) -> 45040.028 | U16: =IFERROR(IF(ISNUMBER(VALUE(TRIM(MID(A16,FIND("-",A16)+1,FIND("km",A16)-FIND("-",A16)-1)))),"Distance + direction + city","Named-region"),"Named-region") -> Named-region | V16: =LOWER(M16) -> mww | W16: =COUNTIFS($A$2:$A$1001,A16,$C$2:$C$1001,C16) -> 1 | X16: =IF(W16>1,"Duplicate","Unique") -> Unique | Y16: =IF(B16<6.5,"<6.5",IF(B16<7,"6.5–6.9",IF(B16<7.5,"7.0–7.4",IF(B16<8,"7.5–7.9","8.0+")))) -> 7.0–7.4 | Z16: =IF(T16="","",YEAR(T16)) -> 2023
A17: M 6.7 - south of the Fiji Islands | B17: 6.7 | C17: 18/04/2023 04:31 | D17: 0 | E17: 3 | F17: green | G17: 1 | H17: 691 | I17: us | J17: 166 | K17: 4.719 | L17: 10 | M17: mww | N17: 595.854 | O17: -22.2844 | P17: 179.391 | Q17: the Fiji Islands | T17: =IF(C17="","",DATE(VALUE(MID(C17,7,4)),VALUE(MID(C17,4,2)),VALUE(MID(C17,1,2)))+TIME(VALUE(MID(C17,12,2)),VALUE(MID(C17,15,2)),0)) -> 45034.188 | U17: =IFERROR(IF(ISNUMBER(VALUE(TRIM(MID(A17,FIND("-",A17)+1,FIND("km",A17)-FIND("-",A17)-1)))),"Distance + direction + city","Named-region"),"Named-region") -> Named-region | V17: =LOWER(M17) -> mww | W17: =COUNTIFS($A$2:$A$1001,A17,$C$2:$C$1001,C17) -> 1 | X17: =IF(W17>1,"Duplicate","Unique") -> Unique | Y17: =IF(B17<6.5,"<6.5",IF(B17<7,"6.5–6.9",IF(B17<7.5,"7.0–7.4",IF(B17<8,"7.5–7.9","8.0+")))) -> 6.5–6.9 | Z17: =IF(T17="","",YEAR(T17)) -> 2023
A18: M 7.0 - 96 km N of Tuban, Indonesia | B18: 7 | C18: 14/04/2023 09:55 | D18: 5 | E18: 3 | F18: green | G18: 0 | H18: 818 | I18: us | J18: 131 | K18: 1.881 | L18: 31 | M18: mww | N18: 594.028 | O18: -6.0255 | P18: 112.033 | Q18: Tuban, Indonesia | S18: Indonesia | T18: =IF(C18="","",DATE(VALUE(MID(C18,7,4)),VALUE(MID(C18,4,2)),VALUE(MID(C18,1,2)))+TIME(VALUE(MID(C18,12,2)),VALUE(MID(C18,15,2)),0)) -> 45030.413 | U18: =IFERROR(IF(ISNUMBER(VALUE(TRIM(MID(A18,FIND("-",A18)+1,FIND("km",A18)-FIND("-",A18)-1)))),"Distance + direction + city","Named-region"),"Named-region") -> Distance + direction + city | V18: =LOWER(M18) -> mww | W18: =COUNTIFS($A$2:$A$1001,A18,$C$2:$C$1001,C18) -> 1 | X18: =IF(W18>1,"Duplicate","Unique") -> Unique | Y18: =IF(B18<6.5,"<6.5",IF(B18<7,"6.5–6.9",IF(B18<7.5,"7.0–7.4",IF(B18<8,"7.5–7.9","8.0+")))) -> 7.0–7.4 | Z18: =IF(T18="","",YEAR(T18)) -> 2023
A19: M 6.5 - near the east coast of the Kamchatka Peninsula, Russia | B19: 6.5 | C19: 03/04/2023 03:06 | D19: 7 | E19: 6 | F19: yellow | G19: 1 | H19: 655 | I19: us | J19: 104 | K19: 0.266 | L19: 30 | M19: mww | N19: 105.631 | O19: 52.7772 | P19: 158.484 | Q19: the Kamchatka Peninsula, Russia | R19: Asia | S19: Russian Federation (the) | T19: =IF(C19="","",DATE(VALUE(MID(C19,7,4)),VALUE(MID(C19,4,2)),VALUE(MID(C19,1,2)))+TIME(VALUE(MID(C19,12,2)),VALUE(MID(C19,15,2)),0)) -> 45019.129 | U19: =IFERROR(IF(ISNUMBER(VALUE(TRIM(MID(A19,FIND("-",A19)+1,FIND("km",A19)-FIND("-",A19)-1)))),"Distance + direction + city","Named-region"),"Named-region") -> Named-region | V19: =LOWER(M19) -> mww | W19: =COUNTIFS($A$2:$A$1001,A19,$C$2:$C$1001,C19) -> 1 | X19: =IF(W19>1,"Duplicate","Unique") -> Unique | Y19: =IF(B19<6.5,"<6.5",IF(B19<7,"6.5–6.9",IF(B19<7.5,"7.0–7.4",IF(B19<8,"7.5–7.9","8.0+")))) -> 6.5–6.9 | Z19: =IF(T19="","",YEAR(T19)) -> 2023
A20: M 7.0 - New Guinea, Papua New Guinea | B20: 7 | C20: 02/04/2023 18:04 | D20: 7 | E20: 7 | F20: green | G20: 1 | H20: 781 | I20: us | J20: 105 | K20: 6.45 | L20: 31 | M20: mww | N20: 62.603 | O20: -4.2924 | P20: 143.155 | Q20: New Guinea, Papua New Guinea | R20: Asia | S20: Papua New Guinea | T20: =IF(C20="","",DATE(VALUE(MID(C20,7,4)),VALUE(MID(C20,4,2)),VALUE(MID(C20,1,2)))+TIME(VALUE(MID(C20,12,2)),VALUE(MID(C20,15,2)),0)) -> 45018.753 | U20: =IFERROR(IF(ISNUMBER(VALUE(TRIM(MID(A20,FIND("-",A20)+1,FIND("km",A20)-FIND("-",A20)-1)))),"Distance + direction + city","Named-region"),"Named-region") -> Named-region | V20: =LOWER(M20) -> mww | W20: =COUNTIFS($A$2:$A$1001,A20,$C$2:$C$1001,C20) -> 1 | X20: =IF(W20>1,"Duplicate","Unique") -> Unique | Y20: =IF(B20<6.5,"<6.5",IF(B20<7,"6.5–6.9",IF(B20<7.5,"7.0–7.4",IF(B20<8,"7.5–7.9","8.0+")))) -> 7.0–7.4 | Z20: =IF(T20="","",YEAR(T20)) -> 2023
A21: M 6.5 - 84 km NNW of San Antonio de los Cobres, Argentina | B21: 6.5 | C21: 22/03/2023 16:00 | D21: 4 | E21: 4 | F21: green | G21: 0 | H21: 656 | I21: us | J21: 97 | K21: 1.622 | L21: 33 | M21: mww | N21: 209.976 | O21: -23.4797 | P21: -66.5108 | Q21: San Antonio de los Cobres, Argentina | R21: South America | S21: Argentina | T21: =IF(C21="","",DATE(VALUE(MID(C21,7,4)),VALUE(MID(C21,4,2)),VALUE(MID(C21,1,2)))+TIME(VALUE(MID(C21,12,2)),VALUE(MID(C21,15,2)),0)) -> 45007.667 | U21: =IFERROR(IF(ISNUMBER(VALUE(TRIM(MID(A21,FIND("-",A21)+1,FIND("km",A21)-FIND("-",A21)-1)))),"Distance + direction + city","Named-region"),"Named-region") -> Distance + direction + city | V21: =LOWER(M21) -> mww | W21: =COUNTIFS($A$2:$A$1001,A21,$C$2:$C$1001,C21) -> 1 | X21: =IF(W21>1,"Duplicate","Unique") -> Unique | Y21: =IF(B21<6.5,"<6.5",IF(B21<7,"6.5–6.9",IF(B21<7.5,"7.0–7.4",IF(B21<8,"7.5–7.9","8.0+")))) -> 6.5–6.9 | Z21: =IF(T21="","",YEAR(T21)) -> 2023
A22: M 6.5 - 40 km SSE of Jurm, Afghanistan | B22: 6.5 | C22: 21/03/2023 16:47 | D22: 7 | E22: 5 | F22: green | G22: 0 | H22: 1350 | I22: us | J22: 134 | K22: 2.53 | L22: 13 | M22: mww | N22: 187.589 | O22: 36.5227 | P22: 70.9787 | Q22: Jurm, Afghanistan | R22: Asia | S22: Afghanistan | T22: =IF(C22="","",DATE(VALUE(MID(C22,7,4)),VALUE(MID(C22,4,2)),VALUE(MID(C22,1,2)))+TIME(VALUE(MID(C22,12,2)),VALUE(MID(C22,15,2)),0)) -> 45006.699 | U22: =IFERROR(IF(ISNUMBER(VALUE(TRIM(MID(A22,FIND("-",A22)+1,FIND("km",A22)-FIND("-",A22)-1)))),"Distance + direction + city","Named-region"),"Named-region") -> Distance + direction + city | V22: =LOWER(M22) -> mww | W22: =COUNTIFS($A$2:$A$1001,A22,$C$2:$C$1001,C22) -> 1 | X22: =IF(W22>1,"Duplicate","Unique") -> Unique | Y22: =IF(B22<6.5,"<6.5",IF(B22<7,"6.5–6.9",IF(B22<7.5,"7.0–7.4",IF(B22<8,"7.5–7.9","8.0+")))) -> 6.5–6.9 | Z22: =IF(T22="","",YEAR(T22)) -> 2023
A23: M 6.8 - near the coast of Ecuador | B23: 6.8 | C23: 18/03/2023 17:12 | D23: 9 | E23: 7 | F23: orange | G23: 1 | H23: 1159 | I23: us | J23: 152 | K23: 0.709 | L23: 28 | M23: mww | N23: 65.842 | O23: -2.851 | P23: -79.8001 | Q23: Ecuador | R23: South America | S23: Ecuador | T23: =IF(C23="","",DATE(VALUE(MID(C23,7,4)),VALUE(MID(C23,4,2)),VALUE(MID(C23,1,2)))+TIME(VALUE(MID(C23,12,2)),VALUE(MID(C23,15,2)),0)) -> 45003.717 | U23: =IFERROR(IF(ISNUMBER(VALUE(TRIM(MID(A23,FIND("-",A23)+1,FIND("km",A23)-FIND("-",A23)-1)))),"Distance + direction + city","Named-region"),"Named-region") -> Named-region | V23: =LOWER(M23) -> mww | W23: =COUNTIFS($A$2:$A$1001,A23,$C$2:$C$1001,C23) -> 1 | X23: =IF(W23>1,"Duplicate","Unique") -> Unique | Y23: =IF(B23<6.5,"<6.5",IF(B23<7,"6.5–6.9",IF(B23<7.5,"7.0–7.4",IF(B23<8,"7.5–7.9","8.0+")))) -> 6.5–6.9 | Z23: =IF(T23="","",YEAR(T23)) -> 2023
A24: M 7.0 - Kermadec Islands region | B24: 7 | C24: 16/03/2023 00:56 | D24: 8 | E24: 5 | F24: green | G24: 1 | H24: 756 | I24: us | J24: 116 | K24: 1.789 | L24: 22 | M24: mww | N24: 22.065 | O24: -30.1147 | P24: -176.112 | Q24: Kermadec Islands region | T24: =IF(C24="","",DATE(VALUE(MID(C24,7,4)),VALUE(MID(C24,4,2)),VALUE(MID(C24,1,2)))+TIME(VALUE(MID(C24,12,2)),VALUE(MID(C24,15,2)),0)) -> 45001.039 | U24: =IFERROR(IF(ISNUMBER(VALUE(TRIM(MID(A24,FIND("-",A24)+1,FIND("km",A24)-FIND("-",A24)-1)))),"Distance + direction + city","Named-region"),"Named-region") -> Named-region | V24: =LOWER(M24) -> mww | W24: =COUNTIFS($A$2:$A$1001,A24,$C$2:$C$1001,C24) -> 1 | X24: =IF(W24>1,"Duplicate","Unique") -> Unique | Y24: =IF(B24<6.5,"<6.5",IF(B24<7,"6.5–6.9",IF(B24<7.5,"7.0–7.4",IF(B24<8,"7.5–7.9","8.0+")))) -> 7.0–7.4 | Z24: =IF(T24="","",YEAR(T24)) -> 2023
A25: M 6.9 - Kermadec Islands, New Zealand | B25: 6.9 | C25: 04/03/2023 06:41 | D25: 5 | E25: 5 | F25: green | G25: 1 | H25: 735 | I25: us | J25: 108 | K25: 0.784 | L25: 18 | M25: mww | N25: 205.681 | O25: -29.4748 | P25: -178.787 | Q25: Kermadec Islands, New Zealand | T25: =IF(C25="","",DATE(VALUE(MID(C25,7,4)),VALUE(MID(C25,4,2)),VALUE(MID(C25,1,2)))+TIME(VALUE(MID(C25,12,2)),VALUE(MID(C25,15,2)),0)) -> 44989.278 | U25: =IFERROR(IF(ISNUMBER(VALUE(TRIM(MID(A25,FIND("-",A25)+1,FIND("km",A25)-FIND("-",A25)-1)))),"Distance + direction + city","Named-region"),"Named-region") -> Named-region | V25: =LOWER(M25) -> mww | W25: =COUNTIFS($A$2:$A$1001,A25,$C$2:$C$1001,C25) -> 1 | X25: =IF(W25>1,"Duplicate","Unique") -> Unique | Y25: =IF(B25<6.5,"<6.5",IF(B25<7,"6.5–6.9",IF(B25<7.5,"7.0–7.4",IF(B25<8,"7.5–7.9","8.0+")))) -> 6.5–6.9 | Z25: =IF(T25="","",YEAR(T25)) -> 2023
A26: M 6.5 - 86 km WSW of Port-Olry, Vanuatu | B26: 6.5 | C26: 02/03/2023 18:04 | D26: 7 | E26: 6 | F26: green | G26: 1 | H26: 653 | I26: us | J26: 66 | K26: 5.483 | L26: 45 | M26: mww | N26: 10 | O26: -15.3597 | P26: 166.385 | Q26: Port-Olry, Vanuatu | T26: =IF(C26="","",DATE(VALUE(MID(C26,7,4)),VALUE(MID(C26,4,2)),VALUE(MID(C26,1,2)))+TIME(VALUE(MID(C26,12,2)),VALUE(MID(C26,15,2)),0)) -> 44987.753 | U26: =IFERROR(IF(ISNUMBER(VALUE(TRIM(MID(A26,FIND("-",A26)+1,FIND("km",A26)-FIND("-",A26)-1)))),"Distance + direction + city","Named-region"),"Named-region") -> Distance + direction + city | V26: =LOWER(M26) -> mww | W26: =COUNTIFS($A$2:$A$1001,A26,$C$2:$C$1001,C26) -> 1 | X26: =IF(W26>1,"Duplicate","Unique") -> Unique | Y26: =IF(B26<6.5,"<6.5",IF(B26<7,"6.5–6.9",IF(B26<7.5,"7.0–7.4",IF(B26<8,"7.5–7.9","8.0+")))) -> 6.5–6.9 | Z26: =IF(T26="","",YEAR(T26)) -> 2023
A27: M 6.5 - 108 km NW of Kimbe, Papua New Guinea | B27: 6.5 | C27: 01/03/2023 05:36 | D27: 4 | E27: 2 | F27: green | G27: 1 | H27: 652 | I27: us | J27: 115 | K27: 2.739 | L27: 20 | M27: mww | N27: 598.925 | O27: -4.8138 | P27: 149.487 | Q27: Kimbe, Papua New Guinea | S27: Papua New Guinea | T27: =IF(C27="","",DATE(VALUE(MID(C27,7,4)),VALUE(MID(C27,4,2)),VALUE(MID(C27,1,2)))+TIME(VALUE(MID(C27,12,2)),VALUE(MID(C27,15,2)),0)) -> 44986.233 | U27: =IFERROR(IF(ISNUMBER(VALUE(TRIM(MID(A27,FIND("-",A27)+1,FIND("km",A27)-FIND("-",A27)-1)))),"Distance + direction + city","Named-region"),"Named-region") -> Distance + direction + city | V27: =LOWER(M27) -> mww | W27: =COUNTIFS($A$2:$A$1001,A27,$C$2:$C$1001,C27) -> 1 | X27: =IF(W27>1,"Duplicate","Unique") -> Unique | Y27: =IF(B27<6.5,"<6.5",IF(B27<7,"6.5–6.9",IF(B27<7.5,"7.0–7.4",IF(B27<8,"7.5–7.9","8.0+")))) -> 6.5–6.9 | Z27: =IF(T27="","",YEAR(T27)) -> 2023
A28: M 6.8 - 67 km W of Murghob, Tajikistan | B28: 6.8 | C28: 23/02/2023 00:37 | D28: 9 | E28: 7 | F28: green | G28: 0 | H28: 737 | I28: us | J28: 128 | K28: 1.783 | L28: 20 | M28: mww | N28: 20.522 | O28: 38.0726 | P28: 73.2077 | Q28: Murghob, Tajikistan | R28: Asia | S28: Tajikistan | T28: =IF(C28="","",DATE(VALUE(MID(C28,7,4)),VALUE(MID(C28,4,2)),VALUE(MID(C28,1,2)))+TIME(VALUE(MID(C28,12,2)),VALUE(MID(C28,15,2)),0)) -> 44980.026 | U28: =IFERROR(IF(ISNUMBER(VALUE(TRIM(MID(A28,FIND("-",A28)+1,FIND("km",A28)-FIND("-",A28)-1)))),"Distance + direction + city","Named-region"),"Named-region") -> Distance + direction + city | V28: =LOWER(M28) -> mww | W28: =COUNTIFS($A$2:$A$1001,A28,$C$2:$C$1001,C28) -> 1 | X28: =IF(W28>1,"Duplicate","Unique") -> Unique | Y28: =IF(B28<6.5,"<6.5",IF(B28<7,"6.5–6.9",IF(B28<7.5,"7.0–7.4",IF(B28<8,"7.5–7.9","8.0+")))) -> 6.5–6.9 | Z28: =IF(T28="","",YEAR(T28)) -> 2023
A29: M 7.5 - 4 km SSE of Ekinözü, Turkey | B29: 7.5 | C29: 06/02/2023 10:24 | D29: 9 | E29: 9 | F29: orange | G29: 0 | H29: 1411 | I29: us | J29: 135 | K29: 0.85 | L29: 17 | M29: mww | N29: 10 | O29: 38.0235 | P29: 37.203 | Q29: Ekinözü, Turkey | R29: Asia | S29: Turkiye | T29: =IF(C29="","",DATE(VALUE(MID(C29,7,4)),VALUE(MID(C29,4,2)),VALUE(MID(C29,1,2)))+TIME(VALUE(MID(C29,12,2)),VALUE(MID(C29,15,2)),0)) -> 44963.433 | U29: =IFERROR(IF(ISNUMBER(VALUE(TRIM(MID(A29,FIND("-",A29)+1,FIND("km",A29)-FIND("-",A29)-1)))),"Distance + direction + city","Named-region"),"Named-region") -> Distance + direction + city | V29: =LOWER(M29) -> mww | W29: =COUNTIFS($A$2:$A$1001,A29,$C$2:$C$1001,C29) -> 1 | X29: =IF(W29>1,"Duplicate","Unique") -> Unique | Y29: =IF(B29<6.5,"<6.5",IF(B29<7,"6.5–6.9",IF(B29<7.5,"7.0–7.4",IF(B29<8,"7.5–7.9","8.0+")))) -> 7.5–7.9 | Z29: =IF(T29="","",YEAR(T29)) -> 2023
A30: M 6.7 - 18 km ESE of Nurdağı, Turkey | B30: 6.7 | C30: 06/02/2023 01:28 | D30: 9 | E30: 8 | F30: yellow | G30: 0 | H30: 800 | I30: us | J30: 108 | K30: 0.218 | L30: 44 | M30: mww | N30: 14.497 | O30: 37.4135 | P30: 36.8306 | Q30: Nurdağı, Turkey | R30: Asia | S30: Turkiye | T30: =IF(C30="","",DATE(VALUE(MID(C30,7,4)),VALUE(MID(C30,4,2)),VALUE(MID(C30,1,2)))+TIME(VALUE(MID(C30,12,2)),VALUE(MID(C30,15,2)),0)) -> 44963.061 | U30: =IFERROR(IF(ISNUMBER(VALUE(TRIM(MID(A30,FIND("-",A30)+1,FIND("km",A30)-FIND("-",A30)-1)))),"Distance + direction + city","Named-region"),"Named-region") -> Distance + direction + city | V30: =LOWER(M30) -> mww | W30: =COUNTIFS($A$2:$A$1001,A30,$C$2:$C$1001,C30) -> 1 | X30: =IF(W30>1,"Duplicate","Unique") -> Unique | Y30: =IF(B30<6.5,"<6.5",IF(B30<7,"6.5–6.9",IF(B30<7.5,"7.0–7.4",IF(B30<8,"7.5–7.9","8.0+")))) -> 6.5–6.9 | Z30: =IF(T30="","",YEAR(T30)) -> 2023
A31: M 7.8 - Central Turkey | B31: 7.8 | C31: 06/02/2023 01:17 | D31: 9 | E31: 9 | F31: red | G31: 0 | H31: 2910 | I31: us | J31: 118 | K31: 1.919 | L31: 32 | M31: mww | N31: 17.925 | O31: 37.2012 | P31: 36.9997 | Q31: Central Turkey | R31: Asia | S31: Turkiye | T31: =IF(C31="","",DATE(VALUE(MID(C31,7,4)),VALUE(MID(C31,4,2)),VALUE(MID(C31,1,2)))+TIME(VALUE(MID(C31,12,2)),VALUE(MID(C31,15,2)),0)) -> 44963.053 | U31: =IFERROR(IF(ISNUMBER(VALUE(TRIM(MID(A31,FIND("-",A31)+1,FIND("km",A31)-FIND("-",A31)-1)))),"Distance + direction + city","Named-region"),"Named-region") -> Named-region | V31: =LOWER(M31) -> mww | W31: =COUNTIFS($A$2:$A$1001,A31,$C$2:$C$1001,C31) -> 1 | X31: =IF(W31>1,"Duplicate","Unique") -> Unique | Y31: =IF(B31<6.5,"<6.5",IF(B31<7,"6.5–6.9",IF(B31<7.5,"7.0–7.4",IF(B31<8,"7.5–7.9","8.0+")))) -> 7.5–7.9 | Z31: =IF(T31="","",YEAR(T31)) -> 2023
A32: M 6.8 - | B32: 6.8 | C32: 20/01/2023 22:09 | D32: 4 | E32: 3 | F32: green | G32: 0 | H32: 718 | I32: us | J32: 60 | K32: 5.129 | L32: 61 | M32: mww | N32: 610.671 | O32: -26.7209 | P32: -63.0394 | R32: South America | S32: Argentina | T32: =IF(C32="","",DATE(VALUE(MID(C32,7,4)),VALUE(MID(C32,4,2)),VALUE(MID(C32,1,2)))+TIME(VALUE(MID(C32,12,2)),VALUE(MID(C32,15,2)),0)) -> 44946.923 | U32: =IFERROR(IF(ISNUMBER(VALUE(TRIM(MID(A32,FIND("-",A32)+1,FIND("km",A32)-FIND("-",A32)-1)))),"Distance + direction + city","Named-region"),"Named-region") -> Named-region | V32: =LOWER(M32) -> mww | W32: =COUNTIFS($A$2:$A$1001,A32,$C$2:$C$1001,C32) -> 1 | X32: =IF(W32>1,"Duplicate","Unique") -> Unique | Y32: =IF(B32<6.5,"<6.5",IF(B32<7,"6.5–6.9",IF(B32<7.5,"7.0–7.4",IF(B32<8,"7.5–7.9","8.0+")))) -> 6.5–6.9 | Z32: =IF(T32="","",YEAR(T32)) -> 2023
A33: M 7.0 - 153 km NW of Tobelo, Indonesia | B33: 7 | C33: 18/01/2023 06:06 | D33: 3 | E33: 5 | F33: green | G33: 1 | H33: 756 | I33: us | J33: 130 | K33: 1.974 | L33: 17 | M33: mwc | N33: 28.566 | O33: 2.7401 | P33: 127.051 | Q33: Tobelo, Indonesia | S33: Indonesia | T33: =IF(C33="","",DATE(VALUE(MID(C33,7,4)),VALUE(MID(C33,4,2)),VALUE(MID(C33,1,2)))+TIME(VALUE(MID(C33,12,2)),VALUE(MID(C33,15,2)),0)) -> 44944.254 | U33: =IFERROR(IF(ISNUMBER(VALUE(TRIM(MID(A33,FIND("-",A33)+1,FIND("km",A33)-FIND("-",A33)-1)))),"Distance + direction + city","Named-region"),"Named-region") -> Distance + direction + city | V33: =LOWER(M33) -> mwc | W33: =COUNTIFS($A$2:$A$1001,A33,$C$2:$C$1001,C33) -> 1 | X33: =IF(W33>1,"Duplicate","Unique") -> Unique | Y33: =IF(B33<6.5,"<6.5",IF(B33<7,"6.5–6.9",IF(B33<7.5,"7.0–7.4",IF(B33<8,"7.5–7.9","8.0+")))) -> 7.0–7.4 | Z33: =IF(T33="","",YEAR(T33)) -> 2023
A34: M 7.6 - Pulau Pulau Tanimbar, Indonesia | B34: 7.6 | C34: 09/01/2023 17:47 | D34: 5 | E34: 7 | F34: green | G34: 0 | H34: 957 | I34: us | J34: 114 | K34: 1.575 | L34: 21 | M34: mww | N34: 105.249 | O34: -7.0852 | P34: 130.039 | Q34: Pulau Pulau Tanimbar, Indonesia | S34: Indonesia | T34: =IF(C34="","",DATE(VALUE(MID(C34,7,4)),VALUE(MID(C34,4,2)),VALUE(MID(C34,1,2)))+TIME(VALUE(MID(C34,12,2)),VALUE(MID(C34,15,2)),0)) -> 44935.741 | U34: =IFERROR(IF(ISNUMBER(VALUE(TRIM(MID(A34,FIND("-",A34)+1,FIND("km",A34)-FIND("-",A34)-1)))),"Distance + direction + city","Named-region"),"Named-region") -> Named-region | V34: =LOWER(M34) -> mww | W34: =COUNTIFS($A$2:$A$1001,A34,$C$2:$C$1001,C34) -> 1 | X34: =IF(W34>1,"Duplicate","Unique") -> Unique | Y34: =IF(B34<6.5,"<6.5",IF(B34<7,"6.5–6.9",IF(B34<7.5,"7.0–7.4",IF(B34<8,"7.5–7.9","8.0+")))) -> 7.5–7.9 | Z34: =IF(T34="","",YEAR(T34)) -> 2023
A35: M 7.0 - Vanuatu | B35: 7 | C35: 08/01/2023 12:32 | D35: 8 | E35: 7 | F35: green | G35: 1 | H35: 768 | I35: us | J35: 116 | K35: 6.096 | L35: 36 | M35: mww | N35: 29 | O35: -14.9383 | P35: 166.878 | Q35: Vanuatu | S35: Vanuatu | T35: =IF(C35="","",DATE(VALUE(MID(C35,7,4)),VALUE(MID(C35,4,2)),VALUE(MID(C35,1,2)))+TIME(VALUE(MID(C35,12,2)),VALUE(MID(C35,15,2)),0)) -> 44934.522 | U35: =IFERROR(IF(ISNUMBER(VALUE(TRIM(MID(A35,FIND("-",A35)+1,FIND("km",A35)-FIND("-",A35)-1)))),"Distance + direction + city","Named-region"),"Named-region") -> Named-region | V35: =LOWER(M35) -> mww | W35: =COUNTIFS($A$2:$A$1001,A35,$C$2:$C$1001,C35) -> 1 | X35: =IF(W35>1,"Duplicate","Unique") -> Unique | Y35: =IF(B35<6.5,"<6.5",IF(B35<7,"6.5–6.9",IF(B35<7.5,"7.0–7.4",IF(B35<8,"7.5–7.9","8.0+")))) -> 7.0–7.4 | Z35: =IF(T35="","",YEAR(T35)) -> 2023
A36: M 6.8 - 109 km NE of Hihifo, Tonga | B36: 6.8 | C36: 04/12/2022 19:24 | D36: 5 | E36: 5 | F36: green | G36: 1 | H36: 720 | I36: us | J36: 152 | K36: 2.587 | L36: 26 | M36: mww | N36: 38 | O36: -15.3983 | P36: -172.968 | Q36: Hihifo, Tonga | T36: =IF(C36="","",DATE(VALUE(MID(C36,7,4)),VALUE(MID(C36,4,2)),VALUE(MID(C36,1,2)))+TIME(VALUE(MID(C36,12,2)),VALUE(MID(C36,15,2)),0)) -> 44899.808 | U36: =IFERROR(IF(ISNUMBER(VALUE(TRIM(MID(A36,FIND("-",A36)+1,FIND("km",A36)-FIND("-",A36)-1)))),"Distance + direction + city","Named-region"),"Named-region") -> Distance + direction + city | V36: =LOWER(M36) -> mww | W36: =COUNTIFS($A$2:$A$1001,A36,$C$2:$C$1001,C36) -> 1 | X36: =IF(W36>1,"Duplicate","Unique") -> Unique | Y36: =IF(B36<6.5,"<6.5",IF(B36<7,"6.5–6.9",IF(B36<7.5,"7.0–7.4",IF(B36<8,"7.5–7.9","8.0+")))) -> 6.5–6.9 | Z36: =IF(T36="","",YEAR(T36)) -> 2022
A37: M 7.0 - 18 km SW of Malango, Solomon Islands | B37: 7 | C37: 22/11/2022 02:03 | D37: 8 | E37: 7 | F37: green | G37: 1 | H37: 768 | I37: us | J37: 117 | K37: 0.509 | L37: 17 | M37: mww | N37: 14 | O37: -9.7963 | P37: 159.596 | Q37: Malango, Solomon Islands | R37: Oceania | S37: Solomon Islands | T37: =IF(C37="","",DATE(VALUE(MID(C37,7,4)),VALUE(MID(C37,4,2)),VALUE(MID(C37,1,2)))+TIME(VALUE(MID(C37,12,2)),VALUE(MID(C37,15,2)),0)) -> 44887.085 | U37: =IFERROR(IF(ISNUMBER(VALUE(TRIM(MID(A37,FIND("-",A37)+1,FIND("km",A37)-FIND("-",A37)-1)))),"Distance + direction + city","Named-region"),"Named-region") -> Distance + direction + city | V37: =LOWER(M37) -> mww | W37: =COUNTIFS($A$2:$A$1001,A37,$C$2:$C$1001,C37) -> 1 | X37: =IF(W37>1,"Duplicate","Unique") -> Unique | Y37: =IF(B37<6.5,"<6.5",IF(B37<7,"6.5–6.9",IF(B37<7.5,"7.0–7.4",IF(B37<8,"7.5–7.9","8.0+")))) -> 7.0–7.4 | Z37: =IF(T37="","",YEAR(T37)) -> 2022
A38: M 6.9 - 204 km SW of Bengkulu, Indonesia | B38: 6.9 | C38: 18/11/2022 13:37 | D38: 4 | E38: 4 | F38: green | G38: 0 | H38: 735 | I38: us | J38: 99 | K38: 2.229 | L38: 34 | M38: mww | N38: 25 | O38: -4.9559 | P38: 100.738 | Q38: Bengkulu, Indonesia | T38: =IF(C38="","",DATE(VALUE(MID(C38,7,4)),VALUE(MID(C38,4,2)),VALUE(MID(C38,1,2)))+TIME(VALUE(MID(C38,12,2)),VALUE(MID(C38,15,2)),0)) -> 44883.567 | U38: =IFERROR(IF(ISNUMBER(VALUE(TRIM(MID(A38,FIND("-",A38)+1,FIND("km",A38)-FIND("-",A38)-1)))),"Distance + direction + city","Named-region"),"Named-region") -> Distance + direction + city | V38: =LOWER(M38) -> mww | W38: =COUNTIFS($A$2:$A$1001,A38,$C$2:$C$1001,C38) -> 1 | X38: =IF(W38>1,"Duplicate","Unique") -> Unique | Y38: =IF(B38<6.5,"<6.5",IF(B38<7,"6.5–6.9",IF(B38<7.5,"7.0–7.4",IF(B38<8,"7.5–7.9","8.0+")))) -> 6.5–6.9 | Z38: =IF(T38="","",YEAR(T38)) -> 2022
A39: M 7.0 - | B39: 7 | C39: 12/11/2022 07:09 | D39: 3 | E39: 3 | F39: green | G39: 1 | H39: 755 | I39: us | J39: 147 | K39: 3.125 | L39: 18 | M39: mww | N39: 579 | O39: -20.0508 | P39: -178.346 | R39: Oceania | S39: Fiji | T39: =IF(C39="","",DATE(VALUE(MID(C39,7,4)),VALUE(MID(C39,4,2)),VALUE(MID(C39,1,2)))+TIME(VALUE(MID(C39,12,2)),VALUE(MID(C39,15,2)),0)) -> 44877.298 | U39: =IFERROR(IF(ISNUMBER(VALUE(TRIM(MID(A39,FIND("-",A39)+1,FIND("km",A39)-FIND("-",A39)-1)))),"Distance + direction + city","Named-region"),"Named-region") -> Named-region | V39: =LOWER(M39) -> mww | W39: =COUNTIFS($A$2:$A$1001,A39,$C$2:$C$1001,C39) -> 1 | X39: =IF(W39>1,"Duplicate","Unique") -> Unique | Y39: =IF(B39<6.5,"<6.5",IF(B39<7,"6.5–6.9",IF(B39<7.5,"7.0–7.4",IF(B39<8,"7.5–7.9","8.0+")))) -> 7.0–7.4 | Z39: =IF(T39="","",YEAR(T39)) -> 2022
A40: M 7.3 - 205 km ESE of Neiafu, Tonga | B40: 7.3 | C40: 11/11/2022 10:48 | D40: 5 | E40: 5 | F40: green | G40: 1 | H40: 833 | I40: us | J40: 149 | K40: 1.865 | L40: 21 | M40: mww | N40: 37 | O40: -19.2918 | P40: -172.129 | Q40: Neiafu, Tonga | T40: =IF(C40="","",DATE(VALUE(MID(C40,7,4)),VALUE(MID(C40,4,2)),VALUE(MID(C40,1,2)))+TIME(VALUE(MID(C40,12,2)),VALUE(MID(C40,15,2)),0)) -> 44876.45 | U40: =IFERROR(IF(ISNUMBER(VALUE(TRIM(MID(A40,FIND("-",A40)+1,FIND("km",A40)-FIND("-",A40)-1)))),"Distance + direction + city","Named-region"),"Named-region") -> Distance + direction + city | V40: =LOWER(M40) -> mww | W40: =COUNTIFS($A$2:$A$1001,A40,$C$2:$C$1001,C40) -> 1 | X40: =IF(W40>1,"Duplicate","Unique") -> Unique | Y40: =IF(B40<6.5,"<6.5",IF(B40<7,"6.5–6.9",IF(B40<7.5,"7.0–7.4",IF(B40<8,"7.5–7.9","8.0+")))) -> 7.0–7.4 | Z40: =IF(T40="","",YEAR(T40)) -> 2022
...

Sheet Task1_Exploration
A1: LAB 3 — TASK 1: EXCEL-BASED EXPLORATION
A3: Metric | B3: Formula / Result | C3: Purpose
A4: Number of records | B4: =COUNTA(Working_Data!A2:A1001) -> 1000 | C4: Total dataset records
A5: Minimum magnitude | B5: =MIN(Working_Data!B2:B1001) -> 6.5 | C5: Magnitude range
A6: Maximum magnitude | B6: =MAX(Working_Data!B2:B1001) -> 9.1 | C6: Magnitude range
A7: Average magnitude | B7: =AVERAGE(Working_Data!B2:B1001) -> 6.94015 | C7: Average magnitude
A8: Minimum depth | B8: =MIN(Working_Data!N2:N1001) -> 2.7 | C8: Depth range
A9: Maximum depth | B9: =MAX(Working_Data!N2:N1001) -> 670.81 | C9: Depth range
A10: Average depth | B10: =AVERAGE(Working_Data!N2:N1001) -> 74.612541 | C10: Average depth
A11: Blank alert | B11: =COUNTBLANK(Working_Data!F2:F1001) -> 551 | C11: Missing alert values
A12: Blank continent | B12: =COUNTBLANK(Working_Data!R2:R1001) -> 716 | C12: Missing continent values
A13: Blank country | B13: =COUNTBLANK(Working_Data!S2:S1001) -> 349 | C13: Missing country values
A14: Blank location | B14: =COUNTBLANK(Working_Data!Q2:Q1001) -> 6 | C14: Missing location values
A17: Magnitude Type | B17: Count | D17: Alert Level | E17: Count | G17: Magnitude Band | H17: Count
A18: Mi | B18: =COUNTIF(Working_Data!M2:M1001,A18) -> 5 | D18: (blank) | E18: =COUNTIF(Working_Data!F2:F1001,"") -> 551 | G18: <6.5 | H18: =COUNTIF(Working_Data!Y2:Y1001,G18) -> 0
A19: mb | B19: =COUNTIF(Working_Data!M2:M1001,A19) -> 4 | D19: green | E19: =COUNTIF(Working_Data!F2:F1001,D19) -> 353 | G19: 6.5–6.9 | H19: =COUNTIF(Working_Data!Y2:Y1001,G19) -> 627
A20: md | B20: =COUNTIF(Working_Data!M2:M1001,A20) -> 2 | D20: yellow | E20: =COUNTIF(Working_Data!F2:F1001,D20) -> 59 | G20: 7.0–7.4 | H20: =COUNTIF(Working_Data!Y2:Y1001,G20) -> 229
A21: ml | B21: =COUNTIF(Working_Data!M2:M1001,A21) -> 1 | D21: orange | E21: =COUNTIF(Working_Data!F2:F1001,D21) -> 24 | G21: 7.5–7.9 | H21: =COUNTIF(Working_Data!Y2:Y1001,G21) -> 112
A22: ms | B22: =COUNTIF(Working_Data!M2:M1001,A22) -> 3 | D22: red | E22: =COUNTIF(Working_Data!F2:F1001,D22) -> 13 | G22: 8.0+ | H22: =COUNTIF(Working_Data!Y2:Y1001,G22) -> 32
A23: mw | B23: =COUNTIF(Working_Data!M2:M1001,A23) -> 51
A24: mwb | B24: =COUNTIF(Working_Data!M2:M1001,A24) -> 100
A25: mwc | B25: =COUNTIF(Working_Data!M2:M1001,A25) -> 332
A26: mww | B26: =COUNTIF(Working_Data!M2:M1001,A26) -> 502
A29: Year | B29: Event Count
A30: 1995 | B30: =COUNTIF(Working_Data!Z2:Z1001,A30) -> 29
A31: 1996 | B31: =COUNTIF(Working_Data!Z2:Z1001,A31) -> 35
A32: 1997 | B32: =COUNTIF(Working_Data!Z2:Z1001,A32) -> 28
A33: 1998 | B33: =COUNTIF(Working_Data!Z2:Z1001,A33) -> 23
A34: 1999 | B34: =COUNTIF(Working_Data!Z2:Z1001,A34) -> 33
A35: 2000 | B35: =COUNTIF(Working_Data!Z2:Z1001,A35) -> 35
A36: 2001 | B36: =COUNTIF(Working_Data!Z2:Z1001,A36) -> 28
A37: 2002 | B37: =COUNTIF(Working_Data!Z2:Z1001,A37) -> 25
A38: 2003 | B38: =COUNTIF(Working_Data!Z2:Z1001,A38) -> 31
A39: 2004 | B39: =COUNTIF(Working_Data!Z2:Z1001,A39) -> 32
A40: 2005 | B40: =COUNTIF(Working_Data!Z2:Z1001,A40) -> 28
A41: 2006 | B41: =COUNTIF(Working_Data!Z2:Z1001,A41) -> 26
A42: 2007 | B42: =COUNTIF(Working_Data!Z2:Z1001,A42) -> 37
A43: 2008 | B43: =COUNTIF(Working_Data!Z2:Z1001,A43) -> 25
A44: 2009 | B44: =COUNTIF(Working_Data!Z2:Z1001,A44) -> 26
A45: 2010 | B45: =COUNTIF(Working_Data!Z2:Z1001,A45) -> 41
...

Sheet Task2_Quality_Audit
A1: LAB 3 — TASK 2: DATA TYPE & QUALITY AUDIT
A3: Column | B3: Data Type | C3: Blank Count | D3: Blank % | E3: Audit / Formula | F3: Finding
A4: title | B4: text | C4: =COUNTBLANK(Working_Data!B2:B1001) -> 0 | D4: =C4/1000 -> 0 | E4: =IFERROR(COUNTBLANK(Working_Data!F2:F1001)/1000,0) -> 0.551 | F4: Review blanks / type as classified
A5: magnitude | B5: numeric | C5: =COUNTBLANK(Working_Data!C2:C1001) -> 0 | D5: =C5/1000 -> 0 | E5: =COUNTBLANK(Working_Data!C2:C1001) -> 0 | F5: Review blanks / type as classified
A6: date_time | B6: text | C6: =COUNTBLANK(Working_Data!D2:D1001) -> 0 | D6: =C6/1000 -> 0 | E6: =COUNTBLANK(Working_Data!D2:D1001) -> 0 | F6: Review blanks / type as classified
A7: cdi | B7: numeric | C7: =COUNTBLANK(Working_Data!E2:E1001) -> 0 | D7: =C7/1000 -> 0 | E7: =COUNTBLANK(Working_Data!E2:E1001) -> 0 | F7: Review blanks / type as classified
A8: mmi | B8: numeric | C8: =COUNTBLANK(Working_Data!F2:F1001) -> 551 | D8: =C8/1000 -> 0.551 | E8: =COUNTBLANK(Working_Data!F2:F1001) -> 551 | F8: Review blanks / type as classified
A9: alert | B9: categorical | C9: =COUNTBLANK(Working_Data!G2:G1001) -> 0 | D9: =C9/1000 -> 0 | E9: =COUNTBLANK(Working_Data!G2:G1001) -> 0 | F9: Review blanks / type as classified
A10: tsunami | B10: numeric | C10: =COUNTBLANK(Working_Data!H2:H1001) -> 0 | D10: =C10/1000 -> 0 | E10: =COUNTBLANK(Working_Data!H2:H1001) -> 0 | F10: Review blanks / type as classified
A11: sig | B11: numeric | C11: =COUNTBLANK(Working_Data!I2:I1001) -> 0 | D11: =C11/1000 -> 0 | E11: =COUNTBLANK(Working_Data!I2:I1001) -> 0 | F11: Review blanks / type as classified
A12: net | B12: categorical | C12: =COUNTBLANK(Working_Data!J2:J1001) -> 0 | D12: =C12/1000 -> 0 | E12: =COUNTBLANK(Working_Data!J2:J1001) -> 0 | F12: Review blanks / type as classified
A13: nst | B13: numeric | C13: =COUNTBLANK(Working_Data!K2:K1001) -> 0 | D13: =C13/1000 -> 0 | E13: =COUNTBLANK(Working_Data!K2:K1001) -> 0 | F13: Review blanks / type as classified
A14: dmin | B14: numeric | C14: =COUNTBLANK(Working_Data!L2:L1001) -> 0 | D14: =C14/1000 -> 0 | E14: =COUNTBLANK(Working_Data!L2:L1001) -> 0 | F14: Review blanks / type as classified
A15: gap | B15: numeric | C15: =COUNTBLANK(Working_Data!M2:M1001) -> 0 | D15: =C15/1000 -> 0 | E15: =COUNTBLANK(Working_Data!M2:M1001) -> 0 | F15: Review blanks / type as classified
A16: magType | B16: categorical | C16: =COUNTBLANK(Working_Data!N2:N1001) -> 0 | D16: =C16/1000 -> 0 | E16: =COUNTBLANK(Working_Data!N2:N1001) -> 0 | F16: Review blanks / type as classified
A17: depth | B17: numeric | C17: =COUNTBLANK(Working_Data!O2:O1001) -> 0 | D17: =C17/1000 -> 0 | E17: =COUNTBLANK(Working_Data!O2:O1001) -> 0 | F17: Review blanks / type as classified
A18: latitude | B18: numeric | C18: =COUNTBLANK(Working_Data!P2:P1001) -> 0 | D18: =C18/1000 -> 0 | E18: =COUNTBLANK(Working_Data!P2:P1001) -> 0 | F18: Review blanks / type as classified
A19: longitude | B19: numeric | C19: =COUNTBLANK(Working_Data!Q2:Q1001) -> 6 | D19: =C19/1000 -> 0.006 | E19: =COUNTBLANK(Working_Data!Q2:Q1001) -> 6 | F19: Review blanks / type as classified
A20: location | B20: text | C20: =COUNTBLANK(Working_Data!R2:R1001) -> 716 | D20: =C20/1000 -> 0.716 | E20: =COUNTBLANK(Working_Data!R2:R1001) -> 716 | F20: Review blanks / type as classified
A21: continent | B21: categorical | C21: =COUNTBLANK(Working_Data!S2:S1001) -> 349 | D21: =C21/1000 -> 0.349 | E21: =COUNTBLANK(Working_Data!S2:S1001) -> 349 | F21: Review blanks / type as classified
A22: country | B22: categorical | C22: =COUNTBLANK(Working_Data!T2:T1001) -> 0 | D22: =C22/1000 -> 0 | E22: =COUNTBLANK(Working_Data!T2:T1001) -> 0 | F22: Review blanks / type as classified
A26: Formula-driven checks
A27: Raw date_time ISNUMBER (first data cell) | B27: =ISNUMBER(Working_Data!C2) -> FALSE | C27: Should be FALSE
A28: Converted datetime ISNUMBER (first data cell) | B28: =ISNUMBER(Working_Data!T2) -> TRUE | C28: Should be TRUE
A29: Distance-pattern title count | B29: =COUNTIF(Working_Data!U2:U1001,"Distance + direction + city") -> 869 | C29: Pattern count
A30: Named-region title count | B30: =COUNTIF(Working_Data!U2:U1001,"Named-region") -> 131 | C30: Pattern count
A31: Duplicated rows | B31: =COUNTIF(Working_Data!X2:X1001,"Duplicate") -> 4 | C31: Rows with duplicate title+timestamp
A32: Unique rows | B32: =COUNTIF(Working_Data!X2:X1001,"Unique") -> 996 | C32: Rows not duplicated
A34: MagType casing check
A35: Distinct before normalization | B35: =COUNTA(Task1_Exploration!A18:A26) -> 9
A36: Distinct after normalization | B36: =SUMPRODUCT(1/COUNTIF(Working_Data!V2:V1001,Working_Data!V2:V1001)) -> 9

Sheet PivotTables
A1: PIVOT TABLE SUMMARIES (formula-driven, refresh automatically)
A3: Alert Level | B3: Event Count | D3: magType (raw) | E3: Count | G3: magType (normalized) | H3: Count
A4: (blank) | B4: =COUNTIF(Working_Data!F2:F1001,"") -> 551 | D4: Mi | E4: =COUNTIF(Working_Data!M2:M1001,D4) -> 5 | G4: mb | H4: =COUNTIF(Working_Data!V2:V1001,G4) -> 4
A5: green | B5: =COUNTIF(Working_Data!F2:F1001,A5) -> 353 | D5: mb | E5: =COUNTIF(Working_Data!M2:M1001,D5) -> 4 | G5: md | H5: =COUNTIF(Working_Data!V2:V1001,G5) -> 2
A6: yellow | B6: =COUNTIF(Working_Data!F2:F1001,A6) -> 59 | D6: md | E6: =COUNTIF(Working_Data!M2:M1001,D6) -> 2 | G6: mi | H6: =COUNTIF(Working_Data!V2:V1001,G6) -> 5
A7: orange | B7: =COUNTIF(Working_Data!F2:F1001,A7) -> 24 | D7: ml | E7: =COUNTIF(Working_Data!M2:M1001,D7) -> 1 | G7: ml | H7: =COUNTIF(Working_Data!V2:V1001,G7) -> 1
A8: red | B8: =COUNTIF(Working_Data!F2:F1001,A8) -> 13 | D8: ms | E8: =COUNTIF(Working_Data!M2:M1001,D8) -> 3 | G8: ms | H8: =COUNTIF(Working_Data!V2:V1001,G8) -> 3
D9: mw | E9: =COUNTIF(Working_Data!M2:M1001,D9) -> 51 | G9: mw | H9: =COUNTIF(Working_Data!V2:V1001,G9) -> 51
D10: mwb | E10: =COUNTIF(Working_Data!M2:M1001,D10) -> 100 | G10: mwb | H10: =COUNTIF(Working_Data!V2:V1001,G10) -> 100
D11: mwc | E11: =COUNTIF(Working_Data!M2:M1001,D11) -> 332 | G11: mwc | H11: =COUNTIF(Working_Data!V2:V1001,G11) -> 332
A12: Magnitude Band | B12: Count | D12: Title Pattern | E12: Count | G12: Duplicate Status | H12: Count
A13: <6.5 | B13: =COUNTIF(Working_Data!Y2:Y1001,A13) -> 0 | D13: Distance + direction + city | E13: =COUNTIF(Working_Data!U2:U1001,D13) -> 869 | G13: Unique | H13: =COUNTIF(Working_Data!X2:X1001,G13) -> 996
A14: 6.5–6.9 | B14: =COUNTIF(Working_Data!Y2:Y1001,A14) -> 627 | D14: Named-region | E14: =COUNTIF(Working_Data!U2:U1001,D14) -> 131 | G14: Duplicate | H14: =COUNTIF(Working_Data!X2:X1001,G14) -> 4
A15: 7.0–7.4 | B15: =COUNTIF(Working_Data!Y2:Y1001,A15) -> 229
A16: 7.5–7.9 | B16: =COUNTIF(Working_Data!Y2:Y1001,A16) -> 112
A17: 8.0+ | B17: =COUNTIF(Working_Data!Y2:Y1001,A17) -> 32
A20: Note: These tables are formula-driven PivotTable-style summaries and recalculate automatically with the dataset.

Sheet Dashboard
A1: EARTHQUAKE DATA EXPLORATION — INTERACTIVE DASHBOARD
A3: KPI | B3: Value | D3: Alert | E3: Count
A4: Records | B4: =COUNTA(Working_Data!A2:A1001) -> 1000 | D4: (blank) | E4: =PivotTables!B4 -> 551
A5: Avg Magnitude | B5: =AVERAGE(Working_Data!B2:B1001) -> 6.94015 | D5: green | E5: =PivotTables!B5 -> 353
A6: Max Magnitude | B6: =MAX(Working_Data!B2:B1001) -> 9.1 | D6: yellow | E6: =PivotTables!B6 -> 59
A7: Min Depth | B7: =MIN(Working_Data!N2:N1001) -> 2.7 | D7: orange | E7: =PivotTables!B7 -> 24
A8: Max Depth | B8: =MAX(Working_Data!N2:N1001) -> 670.81 | D8: red | E8: =PivotTables!B8 -> 13
A9: Blank Alert % | B9: =COUNTBLANK(Working_Data!F2:F1001)/1000 -> 0.551
A10: Blank Continent % | B10: =COUNTBLANK(Working_Data!R2:R1001)/1000 -> 0.716
A11: Blank Country % | B11: =COUNTBLANK(Working_Data!S2:S1001)/1000 -> 0.349
A12: Blank Location % | B12: =COUNTBLANK(Working_Data!Q2:Q1001)/1000 -> 0.006 | D12: Magnitude Band | E12: Count
A13: Duplicate Rows | B13: =COUNTIF(Working_Data!X2:X1001,"Duplicate") -> 4 | D13: <6.5 | E13: =PivotTables!B13 -> 0
D14: 6.5–6.9 | E14: =PivotTables!B14 -> 627
D15: 7.0–7.4 | E15: =PivotTables!B15 -> 229
A16: Dashboard note | B16: Use the Working_Data filters and formula summaries for interactive exploration. All KPI/count outputs are live formulas.

Sheet Data_Type_Classification
A1: 19-COLUMN DATA TYPE CLASSIFICATION
A3: Column | B3: Data Type | C3: Why / Role | D3: Quality Note
A4: title | B4: text | C4: Earthquake title/location string | D4: Mixed title formats
A5: magnitude | B5: numeric | C5: Magnitude value | D5: Range/profile
A6: date_time | B6: datetime (raw is text) | C6: Event date and time | D6: Convert using helper
A7: cdi | B7: numeric | C7: Community intensity measure | D7: May be blank
A8: mmi | B8: numeric | C8: Modified Mercalli intensity | D8: May be blank
A9: alert | B9: categorical | C9: Hazard alert level | D9: Many blanks
A10: tsunami | B10: numeric | C10: Binary tsunami indicator | D10: 0/1
A11: sig | B11: numeric | C11: Significance score | D11: Numeric
A12: net | B12: categorical | C12: Network/source code | D12: Categorical code
A13: nst | B13: numeric | C13: Number of stations | D13: Numeric
A14: dmin | B14: numeric | C14: Minimum distance | D14: Numeric
... A22: country | B22: categorical | C22: Country | D22: Some missing

Sheet Quality_Summary
A1: DATA QUALITY SUMMARY — ISSUE → LAB 4 FIX
A3: Issue Found | B3: Evidence / Formula | C3: Impact | D3: Fix to Apply in Lab 4
A4: Missing alert values | B4: =COUNTBLANK(Working_Data!F2:F1001)/1000 -> 0.551 | C4: Alert unassigned for many events | D4: Keep missing as NA/unknown unless a defensible imputation rule is defined.
A5: Missing continent | B5: =COUNTBLANK(Working_Data!R2:R1001)/1000 -> 0.716 | C5: Geographic grouping incomplete | D5: Retain missing category or derive from coordinates with a documented method.
A6: Missing country | B6: =COUNTBLANK(Working_Data!S2:S1001)/1000 -> 0.349 | C6: Country analysis incomplete | D6: Retain missing category or derive consistently from coordinates.
A7: Missing location | B7: =COUNTBLANK(Working_Data!Q2:Q1001)/1000 -> 0.006 | C7: Location text incomplete | D7: Preserve missing values; avoid unsupported manual filling.
A8: date_time stored as text | B8: =ISNUMBER(Working_Data!C2) -> 0 | C8: Sorting/time analysis can fail | D8: Convert to true datetime (helper column T).
A9: Mixed magType casing | B9: =COUNTA(Working_Data!M2:M1001)-COUNTA(Working_Data!V2:V1001) -> 0 | C9: Same method can split into categories | D9: Normalize magType with LOWER.
A10: Mixed title formats | B10: =COUNTIF(Working_Data!U2:U1001,"Named-region") -> 131 | C10: Distance-based parsing may not work for all rows | D10: Use pattern flag; handle named regions separately.
A11: Near-duplicate events | B11: =COUNTIF(Working_Data!X2:X1001,"Duplicate") -> 4 | C11: Can inflate counts | D11: Review title+timestamp duplicates and deduplicate with a documented rule.

Sheet Formula_Guide
A1: FORMULA / AUDIT GUIDE
A3: Requirement | B3: Implemented In | C3: Formula / Method
A4: COUNTA, COUNTBLANK, COUNTIF, COUNTIFS, ISNUMBER, MIN, MAX, AVERAGE | B4: Task1_Exploration / Task2_Quality_Audit / Working_Data | C4: Live Excel formulas across dataset ranges
A5: PivotTable requirement | B5: PivotTables | C5: Formula-driven pivot-style summaries for alert, magType, magnitude band, title pattern and duplicates
A6: Date conversion | B6: Working_Data column T | C6: DATE + MID + TIME
A7: Title pattern flag | B7: Working_Data column U | C7: FIND + MID + VALUE + ISNUMBER
A8: magType normalization | B8: Working_Data column V | C8: LOWER
A9: Duplicate flag | B9: Working_Data columns W:X | C9: COUNTIFS on title and raw date_time
A10: Magnitude bands | B10: Working_Data column Y | C10: Nested IF
A11: Year helper | B11: Working_Data column Z | C11: YEAR of converted datetime
